<?xml version="1.0"?>

<robot xmlns:xacro="http://www.ros.org/wiki/xacro">

	<xacro:macro name="sih_right" params="parent prefix *origin">
    # SIH Hand

    <joint name="${prefix}_base_joint" type="fixed">
        <parent link="${parent}"/>
        <child link="palm_link"/>
        <xacro:insert_block name="origin" />
    </joint>

    # Palm
    <link name="palm_link">
        <visual>
            <geometry>
                <mesh filename="package://bin_picking_setup/robots/meshes/schunk_sih_right/visual/palm.dae" scale="0.001 0.001 0.001"/>
            </geometry>
            <material name="silver"/>
            <origin rpy="1.57079632679 0 0" xyz="0 0 0"/>
        </visual>
        <collision>
            <geometry>
                <mesh filename="package://bin_picking_setup/robots/meshes/schunk_sih_right/collision/palm.stl" scale="0.001 0.001 0.001"/>
            </geometry>
        </collision>
        <inertial>
            <mass value="0.05"/>
            <origin rpy="0 0 0" xyz="0.0 0.0 0.0"/>
            <inertia ixx="0.0001" ixy="0.0001" ixz="0.0001" iyy="0.0001" iyz="0.0001" izz="0.0001"/>
        </inertial>
    </link>

    # Index finger
    <link name="if_proximal">
        <visual>
            <geometry>
                <mesh filename="package://bin_picking_setup/robots/meshes/schunk_sih_right/visual/if_proximal.dae" scale="0.001 0.001 0.001"/>
            </geometry>
            <material name="silver"/>
            <origin rpy="1.57079632679 0 0" xyz="-0.0435 0 -0.141"/>
        </visual>
        <collision>
            <geometry>
                <mesh filename="package://bin_picking_setup/robots/meshes/schunk_sih_right/collision/if_proximal.stl" scale="0.001 0.001 0.001"/>
            </geometry>
            <origin rpy="0 0 0" xyz="-0.0435 0 -0.141"/>
        </collision>
        <inertial>
            <mass value="0.03"/>
            <origin rpy="0 0 0" xyz="0.0 0.0 0.0"/>
            <inertia ixx="0.0001" ixy="0.0001" ixz="0.0001" iyy="0.0001" iyz="0.0001" izz="0.0001"/>
        </inertial>
    </link>
    <joint name="palm_to_if_proximal" type="revolute">
        <parent link="palm_link"/>
        <child link="if_proximal"/>
        <origin xyz="0.0435 0 0.141"/>
        <axis xyz="1 0 0"/>
        <limit effort="330.0" lower="-1.571" upper="0.0" velocity="2.09439510239"/>
        <dynamics damping="0.1" friction="0"/>

        <dynamics damping="0.1" friction="0"/>
    </joint>
    <link name="if_distal">
        <visual>
            <geometry>
                <mesh filename="package://bin_picking_setup/robots/meshes/schunk_sih_right/visual/if_distal.dae" scale="0.001 0.001 0.001"/>
            </geometry>
            <material name="silver"/>
            <origin rpy="1.57079632679 0 0" xyz="-0.0435 0 -0.189"/>
        </visual>
        <collision>
            <geometry>
                <mesh filename="package://bin_picking_setup/robots/meshes/schunk_sih_right/collision/if_distal.stl" scale="0.001 0.001 0.001"/>
            </geometry>
            <origin rpy="0 0 0" xyz="-0.0435 0 -0.189"/>
        </collision>
        <inertial>
            <mass value="0.03"/>
            <origin rpy="0 0 0" xyz="0.0 0.0 0.0"/>
            <inertia ixx="0.0001" ixy="0.0001" ixz="0.0001" iyy="0.0001" iyz="0.0001" izz="0.0001"/>
        </inertial>
    </link>
    <joint name="if_proximal_to_if_distal" type="revolute">
        <parent link="if_proximal"/>
        <child link="if_distal"/>
        <origin xyz="0 0 0.048"/>
        <axis xyz="1 0 0"/>
        <limit effort="330.0" lower="-1.571" upper="0.0" velocity="2.09439510239"/>
        <dynamics damping="0.1" friction="0"/>
    </joint>

    # Middle finger
    <link name="mf_proximal">
        <visual>
            <geometry>
                <mesh filename="package://bin_picking_setup/robots/meshes/schunk_sih_right/visual/mf_proximal.dae" scale="0.001 0.001 0.001"/>
            </geometry>
            <material name="silver"/>
            <origin rpy="1.57079632679 0 0" xyz="-0.0187 0 -0.141"/>
        </visual>
        <collision>
            <geometry>
                <mesh filename="package://bin_picking_setup/robots/meshes/schunk_sih_right/collision/mf_proximal.stl" scale="0.001 0.001 0.001"/>
            </geometry>
            <origin rpy="0 0 0" xyz="-0.0187 0 -0.141"/>
        </collision>
        <inertial>
            <mass value="0.03"/>
            <origin rpy="0 0 0" xyz="0.0 0.0 0.0"/>
            <inertia ixx="0.0001" ixy="0.0001" ixz="0.0001" iyy="0.0001" iyz="0.0001" izz="0.0001"/>
        </inertial>
    </link>
    <joint name="palm_to_mf_proximal" type="revolute">
        <parent link="palm_link"/>
        <child link="mf_proximal"/>
        <origin xyz="0.0187 0 0.141"/>
        <axis xyz="1 0 0"/>
        <limit effort="330.0" lower="-1.571" upper="0.0" velocity="2.09439510239"/>
        <dynamics damping="0.1" friction="0"/>
    </joint>
    <link name="mf_distal">
        <visual>
            <geometry>
                <mesh filename="package://bin_picking_setup/robots/meshes/schunk_sih_right/visual/mf_distal.dae" scale="0.001 0.001 0.001"/>
            </geometry>
            <material name="silver"/>
            <origin rpy="1.57079632679 0 0" xyz="-0.0187 0 -0.1935"/>
        </visual>
        <collision>
            <geometry>
                <mesh filename="package://bin_picking_setup/robots/meshes/schunk_sih_right/collision/mf_distal.stl" scale="0.001 0.001 0.001"/>
            </geometry>
            <origin rpy="0 0 0" xyz="-0.0187 0 -0.1935"/>
        </collision>
        <inertial>
            <mass value="0.03"/>
            <origin rpy="0 0 0" xyz="0.0 0.0 0.0"/>
            <inertia ixx="0.0001" ixy="0.0001" ixz="0.0001" iyy="0.0001" iyz="0.0001" izz="0.0001"/>
        </inertial>
    </link>
    <joint name="mf_proximal_to_mf_distal" type="revolute">
        <parent link="mf_proximal"/>
        <child link="mf_distal"/>
        <origin xyz="0 0 0.0525"/>
        <axis xyz="1 0 0"/>
        <limit effort="330.0" lower="-1.571" upper="0.0" velocity="2.09439510239"/>
        <dynamics damping="0.1" friction="0"/>
    </joint>

    # Ring finger
    <link name="rf_proximal">
        <visual>
            <geometry>
                <mesh filename="package://bin_picking_setup/robots/meshes/schunk_sih_right/visual/rf_proximal.dae" scale="0.001 0.001 0.001"/>
            </geometry>
            <material name="silver"/>
            <origin rpy="1.57079632679 0 0" xyz="0.0069 0 -0.134"/>
        </visual>
        <collision>
            <geometry>
                <mesh filename="package://bin_picking_setup/robots/meshes/schunk_sih_right/collision/rf_proximal.stl" scale="0.001 0.001 0.001"/>
            </geometry>
            <origin rpy="0 0 0" xyz="0.0069 0 -0.134"/>
        </collision>
        <inertial>
            <mass value="0.03"/>
            <origin rpy="0 0 0" xyz="0.0 0.0 0.0"/>
            <inertia ixx="0.0001" ixy="0.0001" ixz="0.0001" iyy="0.0001" iyz="0.0001" izz="0.0001"/>
        </inertial>
    </link>
    <joint name="palm_to_rf_proximal" type="revolute">
        <parent link="palm_link"/>
        <child link="rf_proximal"/>
        <origin xyz="-0.0069 0 0.134"/>
        <axis xyz="1 0 0"/>
        <limit effort="330.0" lower="-1.571" upper="0.0" velocity="2.09439510239"/>
        <dynamics damping="0.1" friction="0"/>
    </joint>
    <link name="rf_distal">
        <visual>
            <geometry>
                <mesh filename="package://bin_picking_setup/robots/meshes/schunk_sih_right/visual/rf_distal.dae" scale="0.001 0.001 0.001"/>
            </geometry>
            <material name="silver"/>
            <origin rpy="1.57079632679 0 0" xyz="0.0069 0 -0.182"/>
        </visual>
        <collision>
            <geometry>
                <mesh filename="package://bin_picking_setup/robots/meshes/schunk_sih_right/collision/rf_distal.stl" scale="0.001 0.001 0.001"/>
            </geometry>
            <origin rpy="0 0 0" xyz="0.0069 0 -0.182"/>
        </collision>
        <inertial>
            <mass value="0.03"/>
            <origin rpy="0 0 0" xyz="0.0 0.0 0.0"/>
            <inertia ixx="0.0001" ixy="0.0001" ixz="0.0001" iyy="0.0001" iyz="0.0001" izz="0.0001"/>
        </inertial>
    </link>
    <joint name="rf_proximal_to_rf_distal" type="revolute">
        <parent link="rf_proximal"/>
        <child link="rf_distal"/>
        <origin xyz="0 0 0.048"/>
        <axis xyz="1 0 0"/>
        <limit effort="330.0" lower="-1.571" upper="0.0" velocity="2.09439510239"/>
        <dynamics damping="0.1" friction="0"/>
    </joint>

    # Little finger
    <link name="lf_proximal">
        <visual>
            <geometry>
                <mesh filename="package://bin_picking_setup/robots/meshes/schunk_sih_right/visual/lf_proximal.dae" scale="0.001 0.001 0.001"/>
            </geometry>
            <material name="silver"/>
            <origin rpy="1.57079632679 0 0" xyz="0.032 0 -0.1254"/>
        </visual>
        <collision>
            <geometry>
                <mesh filename="package://bin_picking_setup/robots/meshes/schunk_sih_right/collision/lf_proximal.stl" scale="0.001 0.001 0.001"/>
            </geometry>
            <origin rpy="0 0 0" xyz="0.032 0 -0.1254"/>
        </collision>
        <inertial>
            <mass value="0.03"/>
            <origin rpy="0 0 0" xyz="0.0 0.0 0.0"/>
            <inertia ixx="0.0001" ixy="0.0001" ixz="0.0001" iyy="0.0001" iyz="0.0001" izz="0.0001"/>
        </inertial>
    </link>
    <joint name="palm_to_lf_proximal" type="revolute">
        <parent link="palm_link"/>
        <child link="lf_proximal"/>
        <origin xyz="-0.032 0 0.1254"/>
        <axis xyz="1 0 0"/>
        <limit effort="330.0" lower="-1.571" upper="0.0" velocity="2.09439510239"/>
        <dynamics damping="0.1" friction="0"/>
    </joint>
    <link name="lf_distal">
        <visual>
            <geometry>
                <mesh filename="package://bin_picking_setup/robots/meshes/schunk_sih_right/visual/lf_distal.dae" scale="0.001 0.001 0.001"/>
            </geometry>
            <material name="silver"/>
            <origin rpy="1.57079632679 0 0" xyz="0.032 0 -0.1655"/>
        </visual>
        <collision>
            <geometry>
                <mesh filename="package://bin_picking_setup/robots/meshes/schunk_sih_right/collision/lf_distal.stl" scale="0.001 0.001 0.001"/>
            </geometry>
            <origin rpy="0 0 0" xyz="0.032 0 -0.1655"/>
        </collision>
        <inertial>
            <mass value="0.03"/>
            <origin rpy="0 0 0" xyz="0.0 0.0 0.0"/>
            <inertia ixx="0.0001" ixy="0.0001" ixz="0.0001" iyy="0.0001" iyz="0.0001" izz="0.0001"/>
        </inertial>
    </link>
    <joint name="lf_proximal_to_lf_distal" type="revolute">
        <parent link="lf_proximal"/>
        <child link="lf_distal"/>
        <origin xyz="0 0 0.0401"/>
        <axis xyz="1 0 0"/>
        <limit effort="330.0" lower="-1.571" upper="0.0" velocity="2.09439510239"/>
        <dynamics damping="0.1" friction="0"/>
    </joint>

    # Thumb
    <link name="th_proximal">
        <visual>
            <geometry>
                <mesh filename="package://bin_picking_setup/robots/meshes/schunk_sih_right/visual/th_proximal.dae" scale="0.001 0.001 0.001"/>
            </geometry>
            <material name="silver"/>
            <origin rpy="1.57079632679 0 0" xyz="0.034 -0.019 -0.08"/>
        </visual>
        <collision>
            <geometry>
                <mesh filename="package://bin_picking_setup/robots/meshes/schunk_sih_right/collision/th_proximal.stl" scale="0.001 0.001 0.001"/>
            </geometry>
            <origin rpy="0 0 0" xyz="0.034 -0.019 -0.08"/>
        </collision>
        <inertial>
            <mass value="0.03"/>
            <origin rpy="0 0 0" xyz="0.0 0.0 0.0"/>
            <inertia ixx="0.0001" ixy="0.0001" ixz="0.0001" iyy="0.0001" iyz="0.0001" izz="0.0001"/>
        </inertial>
    </link>
    <joint name="palm_to_th_proximal" type="revolute">
        <parent link="palm_link"/>
        <child link="th_proximal"/>
        <origin xyz="-0.034 0.019 0.08"/>
        <axis xyz="0 0 1"/>
        <limit effort="330.0" lower="-1.571" upper="0.0" velocity="2.09439510239"/>
        <dynamics damping="0.1" friction="0"/>
    </joint>
    <link name="th_inter">
        <visual>
            <geometry>
                <mesh filename="package://bin_picking_setup/robots/meshes/schunk_sih_right/visual/th_inter.dae" scale="0.001 0.001 0.001"/>
            </geometry>
            <material name="silver"/>
            <origin rpy="1.57079632679 0 0" xyz="0.058 -0.024 -0.081"/>
        </visual>
        <collision>
            <geometry>
                <mesh filename="package://bin_picking_setup/robots/meshes/schunk_sih_right/collision/th_inter_cvx.stl" scale="0.001 0.001 0.001"/>
            </geometry>
            <origin rpy="0 0 0" xyz="0.058 -0.024 -0.081"/>
        </collision>
        <inertial>
            <mass value="0.03"/>
            <origin rpy="0 0 0" xyz="0.0 0.0 0.0"/>
            <inertia ixx="0.0001" ixy="0.0001" ixz="0.0001" iyy="0.0001" iyz="0.0001" izz="0.0001"/>
        </inertial>
    </link>
    <joint name="th_proximal_to_th_inter" type="revolute">
        <parent link="th_proximal"/>
        <child link="th_inter"/>
        <origin xyz="-0.024 0.005 0.001"/>
        <axis xyz="0 1 0"/>
        <limit effort="330.0" lower="-1.571" upper="0.0" velocity="2.09439510239"/>
        <dynamics damping="0.1" friction="0"/>
    </joint>
    <link name="th_distal">
        <visual>
            <geometry>
                <mesh filename="package://bin_picking_setup/robots/meshes/schunk_sih_right/visual/th_distal.dae" scale="0.001 0.001 0.001"/>
            </geometry>
            <material name="silver"/>
            <origin rpy="1.57079632679 0 0" xyz="0.0971 -0.024 -0.081"/>
        </visual>
        <collision>
            <geometry>
                <mesh filename="package://bin_picking_setup/robots/meshes/schunk_sih_right/collision/th_distal.stl" scale="0.001 0.001 0.001"/>
            </geometry>
            <origin rpy="0 0 0" xyz="0.0971 -0.024 -0.081"/>
        </collision>
        <inertial>
            <mass value="0.03"/>
            <origin rpy="0 0 0" xyz="0.0 0.0 0.0"/>
            <inertia ixx="0.0001" ixy="0.0001" ixz="0.0001" iyy="0.0001" iyz="0.0001" izz="0.0001"/>
        </inertial>
    </link>
    <joint name="th_inter_to_th_distal" type="revolute">
        <parent link="th_inter"/>
        <child link="th_distal"/>
        <origin xyz="-0.0391 0 0"/>
        <axis xyz="0 1 0"/>
        <limit effort="330.0" lower="0.0" upper="1.571" velocity="2.09439510239"/>
        <dynamics damping="0.1" friction="0"/>
    </joint>

</xacro:macro>
</robot>
