<?xml version="1.0"?>

<robot xmlns:xacro="http://www.ros.org/wiki/xacro">

	<xacro:macro name="sih_right" params="parent prefix *origin">

    <material name="silver">
        <color rgba="0.75 0.75 0.75 1"/>
    </material>

    <joint name="${prefix}_base_joint" type="fixed">
        <parent link="${parent}"/>
        <child link="${prefix}_palm_link"/>
        <xacro:insert_block name="origin" />
    </joint>

    # Palm
    <link name="${prefix}_palm_link">
        <visual>
            <geometry>
                <mesh filename="package://learn2grasp/robots/meshes/schunk_sih_right/visual/palm.dae" scale="0.001 0.001 0.001"/>
            </geometry>
            <material name="silver"/>
        </visual>
        <collision>
            <geometry>
                <mesh filename="package://learn2grasp/robots/meshes/schunk_sih_right/collision/palm.stl" scale="0.001 0.001 0.001"/>
            </geometry>
        </collision>
        <inertial>
            <mass value="1.0"/>
            <origin rpy="0 0 0" xyz="0.0 0.0 0.0"/>
            <inertia ixx="0.0001" ixy="0.0001" ixz="0.0001" iyy="0.0001" iyz="0.0001" izz="0.0001"/>
        </inertial>
    </link>

    # Index finger
    <link name="${prefix}_index_proximal_link">
        <visual>
            <geometry>
                <mesh filename="package://learn2grasp/robots/meshes/schunk_sih_right/visual/if_proximal.dae" scale="0.001 0.001 0.001"/>
            </geometry>
            <material name="silver"/>
            <origin rpy="0 0 0" xyz="-0.0435 0 -0.141"/>
        </visual>
        <collision>
            <geometry>
                <mesh filename="package://learn2grasp/robots/meshes/schunk_sih_right/collision/if_proximal.stl" scale="0.001 0.001 0.001"/>
            </geometry>
            <origin rpy="0 0 0" xyz="-0.0435 0 -0.141"/>
        </collision>
        <inertial>
            <mass value="0.100"/>
            <origin rpy="0 0 0" xyz="0.0 0.0 0.0"/>
            <inertia ixx="0.0001" ixy="0.0001" ixz="0.0001" iyy="0.0001" iyz="0.0001" izz="0.0001"/>
        </inertial>
    </link>
    <joint name="${prefix}_index_finger" type="revolute">
        <parent link="${prefix}_palm_link"/>
        <child link="${prefix}_index_proximal_link"/>
        <origin xyz="0.0435 0 0.141"/>
        <axis xyz="1 0 0"/>
        <limit effort="330.0" lower="-1.57" upper="0.0" velocity="2.09439510239"/>
        <dynamics damping="0.1" friction="0"/>
    </joint>
    <link name="${prefix}_index_distal_link">
        <visual>
            <geometry>
                <mesh filename="package://learn2grasp/robots/meshes/schunk_sih_right/visual/if_distal.dae" scale="0.001 0.001 0.001"/>
            </geometry>
            <material name="silver"/>
            <origin rpy="0 0 0" xyz="-0.0435 0 -0.189"/>
        </visual>
        <collision>
            <geometry>
                <mesh filename="package://learn2grasp/robots/meshes/schunk_sih_right/collision/if_distal.stl" scale="0.001 0.001 0.001"/>
            </geometry>
            <origin rpy="0 0 0" xyz="-0.0435 0 -0.189"/>
        </collision>
        <inertial>
            <mass value="0.100"/>
            <origin rpy="0 0 0" xyz="0.0 0.0 0.0"/>
            <inertia ixx="0.0001" ixy="0.0001" ixz="0.0001" iyy="0.0001" iyz="0.0001" izz="0.0001"/>
        </inertial>
    </link>
    <joint name="${prefix}_index_distal_joint" type="revolute">
        <parent link="${prefix}_index_proximal_link"/>
        <child link="${prefix}_index_distal_link"/>
        <origin xyz="0 0 0.048"/>
        <axis xyz="1 0 0"/>
		<mimic joint="${prefix}_index_finger" multiplier="1.0" offset="0" />
        <limit effort="330.0" lower="-1.571" upper="0.0" velocity="2.09439510239"/>
        <dynamics damping="0.1" friction="0"/>
    </joint>

    # Middle finger
    <link name="${prefix}_middle_proximal_link">
        <visual>
            <geometry>
                <mesh filename="package://learn2grasp/robots/meshes/schunk_sih_right/visual/mf_proximal.dae" scale="0.001 0.001 0.001"/>
            </geometry>
            <material name="silver"/>
            <origin rpy="0 0 0" xyz="-0.0187 0 -0.141"/>
        </visual>
        <collision>
            <geometry>
                <mesh filename="package://learn2grasp/robots/meshes/schunk_sih_right/collision/mf_proximal.stl" scale="0.001 0.001 0.001"/>
            </geometry>
            <origin rpy="0 0 0" xyz="-0.0187 0 -0.141"/>
        </collision>
        <inertial>
            <mass value="0.100"/>
            <origin rpy="0 0 0" xyz="0.0 0.0 0.0"/>
            <inertia ixx="0.0001" ixy="0.0001" ixz="0.0001" iyy="0.0001" iyz="0.0001" izz="0.0001"/>
        </inertial>
    </link>
    <joint name="${prefix}_middle_finger" type="revolute">
        <parent link="${prefix}_palm_link"/>
        <child link="${prefix}_middle_proximal_link"/>
        <origin xyz="0.0187 0 0.141"/>
        <axis xyz="1 0 0"/>
        <limit effort="330.0" lower="-1.571" upper="0.0" velocity="2.09439510239"/>
        <dynamics damping="0.1" friction="0"/>
    </joint>
    <link name="${prefix}_middle_distal_link">
        <visual>
            <geometry>
                <mesh filename="package://learn2grasp/robots/meshes/schunk_sih_right/visual/mf_distal.dae" scale="0.001 0.001 0.001"/>
            </geometry>
            <material name="silver"/>
            <origin rpy="0 0 0" xyz="-0.0187 0 -0.1935"/>
        </visual>
        <collision>
            <geometry>
                <mesh filename="package://learn2grasp/robots/meshes/schunk_sih_right/collision/mf_distal.stl" scale="0.001 0.001 0.001"/>
            </geometry>
            <origin rpy="0 0 0" xyz="-0.0187 0 -0.1935"/>
        </collision>
        <inertial>
            <mass value="0.100"/>
            <origin rpy="0 0 0" xyz="0.0 0.0 0.0"/>
            <inertia ixx="0.0001" ixy="0.0001" ixz="0.0001" iyy="0.0001" iyz="0.0001" izz="0.0001"/>
        </inertial>
    </link>
    <joint name="${prefix}_middle_distal_joint" type="revolute">
        <parent link="${prefix}_middle_proximal_link"/>
        <child link="${prefix}_middle_distal_link"/>
        <origin xyz="0 0 0.0525"/>
        <axis xyz="1 0 0"/>
		<mimic joint="${prefix}_middle_finger" multiplier="1.0" offset="0" />
        <limit effort="330.0" lower="-1.571" upper="0.0" velocity="2.09439510239"/>
        <dynamics damping="0.1" friction="0"/>
    </joint>

    # Ring finger
    <link name="${prefix}_ring_proximal_link">
        <visual>
            <geometry>
                <mesh filename="package://learn2grasp/robots/meshes/schunk_sih_right/visual/rf_proximal.dae" scale="0.001 0.001 0.001"/>
            </geometry>
            <material name="silver"/>
            <origin rpy="0 0 0" xyz="0.0069 0 -0.134"/>
        </visual>
        <collision>
            <geometry>
                <mesh filename="package://learn2grasp/robots/meshes/schunk_sih_right/collision/rf_proximal.stl" scale="0.001 0.001 0.001"/>
            </geometry>
            <origin rpy="0 0 0" xyz="0.0069 0 -0.134"/>
        </collision>
        <inertial>
            <mass value="0.100"/>
            <origin rpy="0 0 0" xyz="0.0 0.0 0.0"/>
            <inertia ixx="0.0001" ixy="0.0001" ixz="0.0001" iyy="0.0001" iyz="0.0001" izz="0.0001"/>
        </inertial>
    </link>
    <joint name="${prefix}_ring_finger" type="revolute">
        <parent link="${prefix}_palm_link"/>
        <child link="${prefix}_ring_proximal_link"/>
        <origin xyz="-0.0069 0 0.134"/>
        <axis xyz="1 0 0"/>
        <limit effort="330.0" lower="-1.571" upper="0.0" velocity="2.09439510239"/>
        <dynamics damping="0.1" friction="0"/>
    </joint>
    <link name="${prefix}_ring_distal_link">
        <visual>
            <geometry>
                <mesh filename="package://learn2grasp/robots/meshes/schunk_sih_right/visual/rf_distal.dae" scale="0.001 0.001 0.001"/>
            </geometry>
            <material name="silver"/>
            <origin rpy="0 0 0" xyz="0.0069 0 -0.182"/>
        </visual>
        <collision>
            <geometry>
                <mesh filename="package://learn2grasp/robots/meshes/schunk_sih_right/collision/rf_distal.stl" scale="0.001 0.001 0.001"/>
            </geometry>
            <origin rpy="0 0 0" xyz="0.0069 0 -0.182"/>
        </collision>
        <inertial>
            <mass value="0.100"/>
            <origin rpy="0 0 0" xyz="0.0 0.0 0.0"/>
            <inertia ixx="0.0001" ixy="0.0001" ixz="0.0001" iyy="0.0001" iyz="0.0001" izz="0.0001"/>
        </inertial>
    </link>
    <joint name="${prefix}_ring_distal_joint" type="revolute">
        <parent link="${prefix}_ring_proximal_link"/>
        <child link="${prefix}_ring_distal_link"/>
        <origin xyz="0 0 0.048"/>
        <axis xyz="1 0 0"/>
		<mimic joint="${prefix}_ring_finger" multiplier="1.0" offset="0" />
        <limit effort="330.0" lower="-1.571" upper="0.0" velocity="2.09439510239"/>
        <dynamics damping="0.1" friction="0"/>
    </joint>

    # Little finger
    <link name="${prefix}_pinky_proximal_link">
        <visual>
            <geometry>
                <mesh filename="package://learn2grasp/robots/meshes/schunk_sih_right/visual/lf_proximal.dae" scale="0.001 0.001 0.001"/>
            </geometry>
            <material name="silver"/>
            <origin rpy="0 0 0" xyz="0.032 0 -0.1254"/>
        </visual>
        <collision>
            <geometry>
                <mesh filename="package://learn2grasp/robots/meshes/schunk_sih_right/collision/lf_proximal.stl" scale="0.001 0.001 0.001"/>
            </geometry>
            <origin rpy="0 0 0" xyz="0.032 0 -0.1254"/>
        </collision>
        <inertial>
            <mass value="0.100"/>
            <origin rpy="0 0 0" xyz="0.0 0.0 0.0"/>
            <inertia ixx="0.0001" ixy="0.0001" ixz="0.0001" iyy="0.0001" iyz="0.0001" izz="0.0001"/>
        </inertial>
    </link>
    <joint name="${prefix}_pinky_proximal_joint" type="revolute">
        <parent link="${prefix}_palm_link"/>
        <child link="${prefix}_pinky_proximal_link"/>
        <origin xyz="-0.032 0 0.1254"/>
        <axis xyz="1 0 0"/>
		<mimic joint="${prefix}_ring_finger" multiplier="1.0" offset="0" />
        <limit effort="330.0" lower="-1.571" upper="0.0" velocity="2.09439510239"/>
        <dynamics damping="0.1" friction="0"/>
    </joint>
    <link name="${prefix}_pinky_distal_link">
        <visual>
            <geometry>
                <mesh filename="package://learn2grasp/robots/meshes/schunk_sih_right/visual/lf_distal.dae" scale="0.001 0.001 0.001"/>
            </geometry>
            <material name="silver"/>
            <origin rpy="0 0 0" xyz="0.032 0 -0.1655"/>
        </visual>
        <collision>
            <geometry>
                <mesh filename="package://learn2grasp/robots/meshes/schunk_sih_right/collision/lf_distal.stl" scale="0.001 0.001 0.001"/>
            </geometry>
            <origin rpy="0 0 0" xyz="0.032 0 -0.1655"/>
        </collision>
        <inertial>
            <mass value="0.100"/>
            <origin rpy="0 0 0" xyz="0.0 0.0 0.0"/>
            <inertia ixx="0.0001" ixy="0.0001" ixz="0.0001" iyy="0.0001" iyz="0.0001" izz="0.0001"/>
        </inertial>
    </link>
    <joint name="${prefix}_pinky_distal_joint" type="revolute">
        <parent link="${prefix}_pinky_proximal_link"/>
        <child link="${prefix}_pinky_distal_link"/>
        <origin xyz="0 0 0.0401"/>
        <axis xyz="1 0 0"/>
		<mimic joint="${prefix}_pinky_proximal_joint" multiplier="1.0" offset="0" />
        <limit effort="330.0" lower="-1.571" upper="0.0" velocity="2.09439510239"/>
        <dynamics damping="0.1" friction="0"/>
    </joint>

    # Thumb
    <link name="${prefix}_thumb_proximal_link">
        <visual>
            <geometry>
                <mesh filename="package://learn2grasp/robots/meshes/schunk_sih_right/visual/th_proximal.dae" scale="0.001 0.001 0.001"/>
            </geometry>
            <material name="silver"/>
            <origin rpy="0 0 0" xyz="0.034 -0.019 -0.08"/>
        </visual>
        <collision>
            <geometry>
                <mesh filename="package://learn2grasp/robots/meshes/schunk_sih_right/collision/th_proximal.stl" scale="0.001 0.001 0.001"/>
            </geometry>
            <origin rpy="0 0 0" xyz="0.034 -0.019 -0.08"/>
        </collision>
        <inertial>
            <mass value="0.100"/>
            <origin rpy="0 0 0" xyz="0.0 0.0 0.0"/>
            <inertia ixx="0.0001" ixy="0.0001" ixz="0.0001" iyy="0.0001" iyz="0.0001" izz="0.0001"/>
        </inertial>
    </link>
    <joint name="${prefix}_thumb_opposition" type="revolute">
        <parent link="${prefix}_palm_link"/>
        <child link="${prefix}_thumb_proximal_link"/>
        <origin xyz="-0.034 0.019 0.08"/>
        <axis xyz="0 0 1"/>
        <limit effort="330.0" lower="-1.571" upper="0.0" velocity="2.09439510239"/>
        <dynamics damping="0.1" friction="0"/>
    </joint>
    <link name="${prefix}_thumb_inter_link">
        <visual>
            <geometry>
                <mesh filename="package://learn2grasp/robots/meshes/schunk_sih_right/visual/th_inter.dae" scale="0.001 0.001 0.001"/>
            </geometry>
            <material name="silver"/>
            <origin rpy="0 0 0" xyz="0.058 -0.024 -0.081"/>
        </visual>
        <collision>
            <geometry>
                <mesh filename="package://learn2grasp/robots/meshes/schunk_sih_right/collision/th_inter_cvx.stl" scale="0.001 0.001 0.001"/>
            </geometry>
            <origin rpy="0 0 0" xyz="0.058 -0.024 -0.081"/>
        </collision>
        <inertial>
            <mass value="0.100"/>
            <origin rpy="0 0 0" xyz="0.0 0.0 0.0"/>
            <inertia ixx="0.0001" ixy="0.0001" ixz="0.0001" iyy="0.0001" iyz="0.0001" izz="0.0001"/>
        </inertial>
    </link>
    <joint name="${prefix}_thumb_flexion" type="revolute">
        <parent link="${prefix}_thumb_proximal_link"/>
        <child link="${prefix}_thumb_inter_link"/>
        <origin xyz="-0.024 0.005 0.001"/>
        <axis xyz="0 1 0"/>
        <limit effort="330.0" lower="0.0" upper="1.571" velocity="2.09439510239"/>
        <dynamics damping="0.1" friction="0"/>
    </joint>
    <link name="${prefix}_thumb_distal_link">
        <visual>
            <geometry>
                <mesh filename="package://learn2grasp/robots/meshes/schunk_sih_right/visual/th_distal.dae" scale="0.001 0.001 0.001"/>
            </geometry>
            <material name="silver"/>
            <origin rpy="0 0 0" xyz="0.0971 -0.024 -0.081"/>
        </visual>
        <collision>
            <geometry>
                <mesh filename="package://learn2grasp/robots/meshes/schunk_sih_right/collision/th_distal.stl" scale="0.001 0.001 0.001"/>
            </geometry>
            <origin rpy="0 0 0" xyz="0.0971 -0.024 -0.081"/>
        </collision>
        <inertial>
            <mass value="0.100"/>
            <origin rpy="0 0 0" xyz="0.0 0.0 0.0"/>
            <inertia ixx="0.0001" ixy="0.0001" ixz="0.0001" iyy="0.0001" iyz="0.0001" izz="0.0001"/>
        </inertial>
    </link>
    <joint name="${prefix}_thumb_distal" type="revolute">
        <parent link="${prefix}_thumb_inter_link"/>
        <child link="${prefix}_thumb_distal_link"/>
        <origin xyz="-0.0391 0 0"/>
        <axis xyz="0 1 0"/>
        <limit effort="330.0" lower="0.0" upper="1.571" velocity="2.09439510239"/>
        <dynamics damping="0.1" friction="0"/>
    </joint>
</xacro:macro>
</robot>

