<?xml version="1.0" ?>
<robot name="kuka_lbr_iiwa_14_r820" xmlns:xacro="http://wiki.ros.org/xacro">
  
  <xacro:include filename="$(find LBR_iiwa)/urdf/lbr_iiwa_14_r820_macro.xacro"/>
  <xacro:kuka_lbr_iiwa_14_r820 prefix="kuka_"/>
  
  <link name="gripper_base_link">
    <inertial>
      <origin xyz="0 0 0" rpy="0 0 0"/>
      <mass value="1.2"/>
      <inertia ixx="1" ixy="0" ixz="0" iyy="1" iyz="0" izz="1"/>
    </inertial>
    <visual>
      <origin xyz="0 0 -0.09" rpy="0 0 0" />
      <geometry> <box size="0.05 0.05 0.03" /> </geometry>
      <material name="grey"/>
    </visual>
    <collision>
      <origin xyz="0 0 -0.09" rpy="0 0 0" />
      <geometry> <box size="0.05 0.05 0.03" /> </geometry>
    </collision>
  </link>
  
  <xacro:macro name="gripper" params="side">
  <link name="${side}_finger">
    <inertial>
      <origin xyz="0 0 0" rpy="0 0 0"/>
      <mass value="0.1"/>
      <inertia ixx="0.01" ixy="0" ixz="0" iyy="0.01" iyz="0" izz="0.01"/>
    </inertial>
    <visual>
      <origin xyz="0 0 0.04" rpy="0 0 0" />
      <geometry> <box size="0.01 0.01 0.08" /> </geometry>
      <material name="grey"/>
    </visual>
    <collision>
      <origin xyz="0 0 -0.05" rpy="0 0 0" />
      <geometry> <box size="0.01 0.01 0.08" /> </geometry>
    </collision>
  </link>
  
  <link name="${side}_finger_base">
      <inertial>
        <origin xyz="0 0 0" rpy="0 0 0"/>
        <mass value="0.2"/>
        <inertia ixx="0.1" ixy="0" ixz="0" iyy="0.1" iyz="0" izz="0.1"/>
      </inertial>
    <visual>
      <origin xyz="0 0 0" rpy="0 0 0" />
      <geometry> <mesh filename="package://LBR_iiwa/meshes/collision/finger_base_${side}.stl" /> </geometry>
      <material name="grey"/>
    </visual>
    <collision>
      <origin xyz="0 0 0" rpy="0 0 0" />
      <geometry> <mesh filename="package://LBR_iiwa/meshes/collision/finger_base_${side}.stl" /> </geometry>
    </collision>
  </link>
  
  <link name="${side}_finger_tip">
      <inertial>
        <origin xyz="0 0 0" rpy="0 0 0"/>
        <mass value="0.2"/>
        <inertia ixx="0.1" ixy="0" ixz="0" iyy="0.1" iyz="0" izz="0.1"/>
      </inertial>
    <visual>
      <origin xyz="0 0 0.02" rpy="0 0 0" />
      <geometry> <mesh filename="package://LBR_iiwa/meshes/collision/finger_tip_${side}.stl" /> </geometry>
      <material name="grey"/>
    </visual>
    <collision>
      <origin xyz="0 0 0" rpy="0 0 0" />
      <geometry> <mesh filename="package://LBR_iiwa/meshes/collision/finger_tip_${side}.stl" /> </geometry>
    </collision>
  </link>
  
  <joint name="base_${side}_finger_joint" type="revolute">
    <origin xyz="0 0 -0.08" rpy="0 0 0" />
    <parent link="gripper_base_link" />
    <child link="${side}_finger" />
    <axis xyz="0 1 0" />
    <limit lower="${-0.5 if side=='left' else 0.05}" upper="${-0.05 if side=='left' else 0.5}" effort="10" velocity="1" />
  </joint>
  <joint name="${side}_finger_base_joint" type="fixed">
    <origin xyz="0 0 0.08" rpy="0 0 0" />
    <parent link="${side}_finger" />
    <child link="${side}_finger_base" />
  </joint>
  <joint name="${side}_base_tip_joint" type="revolute">
    <origin xyz="0 0 0.04" rpy="0 0 0" />
    <parent link="${side}_finger_base" />
    <child link="${side}_finger_tip" />
    <axis xyz="0 1 0" />
    <limit lower="${-0.3 if side=='left' else -0.1}" upper="${0.1 if side=='left' else 0.3}" effort="10" velocity="1" />
  </joint>
  </xacro:macro>
  
  <joint name="kuka_to_gripper_joint" type="fixed">
    <origin xyz="0 0 0.23" rpy="0 0 0"/>
    <parent link="kuka_link_7"/>
    <child link="gripper_base_link"/>
  </joint>
  
  <xacro:gripper side="left"/>
  <xacro:gripper side="right"/>
  
</robot>
