<?xml version="1.0" ?>
<!-- =================================================================================== -->
<!-- |    This document was autogenerated by xacro from /home/softbankrobotics/PycharmProjects/qdmbs_joint/grab-babling/gym-grabbing/gym_grabbing/envs/robots/learn2grasp/learn2grasp.urdf.xacro | -->
<!-- |    EDITING THIS FILE BY HAND IS NOT RECOMMENDED                                 | -->
<!-- =================================================================================== -->
<robot name="ur5_sih_schunk">
  <material name="gray">
    <color rgba="0.5 0.5 0.5 1"/>
  </material>
  <material name="brown">
    <color rgba="0.9 0.45 0.0 1"/>
  </material>
  <material name="white">
    <color rgba="1.0 1.0 1.0 1"/>
  </material>
  <material name="collision_only_white">
    <color rgba="1.0 1.0 1.0 0.05"/>
  </material>
  <!--xacro:arg name="name" default="ur5"/-->
  <!--xacro:include filename="$(find ur_description)/urdf/ur.urdf.xacro"/-->
  <!-- measured from model -->
  <!--property name="shoulder_height" value="0.089159" /-->
  <!--property name="shoulder_offset" value="0.13585" /-->
  <!-- shoulder_offset - elbow_offset + wrist_1_length = 0.10915 -->
  <!--property name="upper_arm_length" value="0.42500" /-->
  <!--property name="elbow_offset" value="0.1197" /-->
  <!-- CAD measured -->
  <!--property name="forearm_length" value="0.39225" /-->
  <!--property name="wrist_1_length" value="0.093" /-->
  <!-- CAD measured -->
  <!--property name="wrist_2_length" value="0.09465" /-->
  <!-- In CAD this distance is 0.930, but in the spec it is 0.09465 -->
  <!--property name="wrist_3_length" value="0.0823" /-->
  <!-- manually measured -->
  <link name="base_link">
    <visual>
      <geometry>
        <mesh filename="package://ur_description/meshes/ur5/visual/base.dae"/>
      </geometry>
      <material name="LightGrey">
        <color rgba="0.7 0.7 0.7 1.0"/>
      </material>
    </visual>
    <collision>
      <geometry>
        <mesh filename="package://ur_description/meshes/ur5/collision/base.stl"/>
      </geometry>
    </collision>
    <inertial>
      <mass value="4.0"/>
      <origin rpy="0 0 0" xyz="0.0 0.0 0.0"/>
      <inertia ixx="0.00443333156" ixy="0.0" ixz="0.0" iyy="0.00443333156" iyz="0.0" izz="0.0072"/>
    </inertial>
  </link>
  <joint name="shoulder_pan_joint" type="revolute">
    <parent link="base_link"/>
    <child link="shoulder_link"/>
    <origin rpy="0.0 0.0 0.0" xyz="0.0 0.0 0.089159"/>
    <axis xyz="0 0 1"/>
    <limit effort="150.0" lower="-3.141592653589793" upper="3.141592653589793" velocity="0.8"/>
    <dynamics damping="0.0" friction="0.0"/>
  </joint>
  <link name="shoulder_link">
    <visual>
      <geometry>
        <mesh filename="package://ur_description/meshes/ur5/visual/shoulder.dae"/>
      </geometry>
      <material name="LightGrey">
        <color rgba="0.7 0.7 0.7 1.0"/>
      </material>
    </visual>
    <collision>
      <geometry>
        <mesh filename="package://ur_description/meshes/ur5/collision/shoulder.stl"/>
      </geometry>
    </collision>
    <inertial>
      <mass value="3.7"/>
      <origin rpy="0 0 0" xyz="0.0 0.0 0.0"/>
      <inertia ixx="0.010267495893" ixy="0.0" ixz="0.0" iyy="0.010267495893" iyz="0.0" izz="0.00666"/>
    </inertial>
  </link>
  <joint name="shoulder_lift_joint" type="revolute">
    <parent link="shoulder_link"/>
    <child link="upper_arm_link"/>
    <origin rpy="0.0 1.5707963267948966 0.0" xyz="0.0 0.13585 0.0"/>
    <axis xyz="0 1 0"/>
    <limit effort="150.0" lower="-3.141592653589793" upper="3.141592653589793" velocity="0.8"/>
    <dynamics damping="0.0" friction="0.0"/>
  </joint>
  <link name="upper_arm_link">
    <visual>
      <geometry>
        <mesh filename="package://ur_description/meshes/ur5/visual/upperarm.dae"/>
      </geometry>
      <material name="LightGrey">
        <color rgba="0.7 0.7 0.7 1.0"/>
      </material>
    </visual>
    <collision>
      <geometry>
        <mesh filename="package://ur_description/meshes/ur5/collision/upperarm.stl"/>
      </geometry>
    </collision>
    <inertial>
      <mass value="8.393"/>
      <origin rpy="0 0 0" xyz="0.0 0.0 0.28"/>
      <inertia ixx="0.22689067591036005" ixy="0.0" ixz="0.0" iyy="0.22689067591036005" iyz="0.0" izz="0.0151074"/>
    </inertial>
  </link>
  <joint name="elbow_joint" type="revolute">
    <parent link="upper_arm_link"/>
    <child link="forearm_link"/>
    <origin rpy="0.0 0.0 0.0" xyz="0.0 -0.1197 0.425"/>
    <axis xyz="0 1 0"/>
    <limit effort="150.0" lower="-3.141592653589793" upper="3.141592653589793" velocity="0.6"/>
    <dynamics damping="0.0" friction="0.0"/>
  </joint>
  <link name="forearm_link">
    <visual>
      <geometry>
        <mesh filename="package://ur_description/meshes/ur5/visual/forearm.dae"/>
      </geometry>
      <material name="LightGrey">
        <color rgba="0.7 0.7 0.7 1.0"/>
      </material>
    </visual>
    <collision>
      <geometry>
        <mesh filename="package://ur_description/meshes/ur5/collision/forearm.stl"/>
      </geometry>
    </collision>
    <inertial>
      <mass value="2.275"/>
      <origin rpy="0 0 0" xyz="0.0 0.0 0.196125"/>
      <inertia ixx="0.03121679102890359" ixy="0.0" ixz="0.0" iyy="0.03121679102890359" iyz="0.0" izz="0.004095"/>
    </inertial>
  </link>
  <joint name="wrist_1_joint" type="revolute">
    <parent link="forearm_link"/>
    <child link="wrist_1_link"/>
    <origin rpy="0.0 1.5707963267948966 0.0" xyz="0.0 0.0 0.39225"/>
    <axis xyz="0 1 0"/>
    <limit effort="28.0" lower="-3.141592653589793" upper="3.141592653589793" velocity="0.6"/>
    <dynamics damping="0.0" friction="0.0"/>
  </joint>
  <link name="wrist_1_link">
    <visual>
      <geometry>
        <mesh filename="package://ur_description/meshes/ur5/visual/wrist1.dae"/>
      </geometry>
      <material name="LightGrey">
        <color rgba="0.7 0.7 0.7 1.0"/>
      </material>
    </visual>
    <collision>
      <geometry>
        <mesh filename="package://ur_description/meshes/ur5/collision/wrist1.stl"/>
      </geometry>
    </collision>
    <inertial>
      <mass value="1.219"/>
      <origin rpy="0 0 0" xyz="0.0 0.093 0.0"/>
      <inertia ixx="0.0025598989760400002" ixy="0.0" ixz="0.0" iyy="0.0025598989760400002" iyz="0.0" izz="0.0021942"/>
    </inertial>
  </link>
  <joint name="wrist_2_joint" type="revolute">
    <parent link="wrist_1_link"/>
    <child link="wrist_2_link"/>
    <origin rpy="0.0 0.0 0.0" xyz="0.0 0.093 0.0"/>
    <axis xyz="0 0 1"/>
    <limit effort="28.0" lower="-3.141592653589793" upper="3.141592653589793" velocity="0.6"/>
    <dynamics damping="0.0" friction="0.0"/>
  </joint>
  <link name="wrist_2_link">
    <visual>
      <geometry>
        <mesh filename="package://ur_description/meshes/ur5/visual/wrist2.dae"/>
      </geometry>
      <material name="LightGrey">
        <color rgba="0.7 0.7 0.7 1.0"/>
      </material>
    </visual>
    <collision>
      <geometry>
        <mesh filename="package://ur_description/meshes/ur5/collision/wrist2.stl"/>
      </geometry>
    </collision>
    <inertial>
      <mass value="1.219"/>
      <origin rpy="0 0 0" xyz="0.0 0.0 0.09465"/>
      <inertia ixx="0.0025598989760400002" ixy="0.0" ixz="0.0" iyy="0.0025598989760400002" iyz="0.0" izz="0.0021942"/>
    </inertial>
  </link>
  <joint name="wrist_3_joint" type="revolute">
    <parent link="wrist_2_link"/>
    <child link="wrist_3_link"/>
    <origin rpy="0.0 0.0 0.0" xyz="0.0 0.0 0.09465"/>
    <axis xyz="0 1 0"/>
    <limit effort="28.0" lower="-3.141592653589793" upper="3.141592653589793" velocity="0.6"/>
    <dynamics damping="0.0" friction="0.0"/>
  </joint>
  <link name="wrist_3_link">
    <visual>
      <geometry>
        <mesh filename="package://ur_description/meshes/ur5/visual/wrist3.dae"/>
      </geometry>
      <material name="LightGrey">
        <color rgba="0.7 0.7 0.7 1.0"/>
      </material>
    </visual>
    <collision>
      <geometry>
        <mesh filename="package://ur_description/meshes/ur5/collision/wrist3.stl"/>
      </geometry>
    </collision>
    <inertial>
      <mass value="0.1879"/>
      <origin rpy="1.5707963267948966 0 0" xyz="0.0 0.06505 0.0"/>
      <inertia ixx="8.469589112163e-05" ixy="0.0" ixz="0.0" iyy="8.469589112163e-05" iyz="0.0" izz="0.0001321171875"/>
    </inertial>
  </link>
  <joint name="ee_fixed_joint" type="fixed">
    <parent link="wrist_3_link"/>
    <child link="ee_link"/>
    <origin rpy="0.0 0.0 1.5707963267948966" xyz="0.0 0.0823 0.0"/>
  </joint>
  <link name="ee_link">
    <collision>
      <geometry>
        <box size="0.01 0.01 0.01"/>
      </geometry>
      <origin rpy="0 0 0" xyz="-0.01 0 0"/>
    </collision>
  </link>
  <transmission name="shoulder_pan_trans">
    <type>transmission_interface/SimpleTransmission</type>
    <joint name="shoulder_pan_joint">
      <hardwareInterface>hardware_interface/PositionJointInterface</hardwareInterface>
    </joint>
    <actuator name="shoulder_pan_motor">
      <mechanicalReduction>1</mechanicalReduction>
    </actuator>
  </transmission>
  <transmission name="shoulder_lift_trans">
    <type>transmission_interface/SimpleTransmission</type>
    <joint name="shoulder_lift_joint">
      <hardwareInterface>hardware_interface/PositionJointInterface</hardwareInterface>
    </joint>
    <actuator name="shoulder_lift_motor">
      <mechanicalReduction>1</mechanicalReduction>
    </actuator>
  </transmission>
  <transmission name="elbow_trans">
    <type>transmission_interface/SimpleTransmission</type>
    <joint name="elbow_joint">
      <hardwareInterface>hardware_interface/PositionJointInterface</hardwareInterface>
    </joint>
    <actuator name="elbow_motor">
      <mechanicalReduction>1</mechanicalReduction>
    </actuator>
  </transmission>
  <transmission name="wrist_1_trans">
    <type>transmission_interface/SimpleTransmission</type>
    <joint name="wrist_1_joint">
      <hardwareInterface>hardware_interface/PositionJointInterface</hardwareInterface>
    </joint>
    <actuator name="wrist_1_motor">
      <mechanicalReduction>1</mechanicalReduction>
    </actuator>
  </transmission>
  <transmission name="wrist_2_trans">
    <type>transmission_interface/SimpleTransmission</type>
    <joint name="wrist_2_joint">
      <hardwareInterface>hardware_interface/PositionJointInterface</hardwareInterface>
    </joint>
    <actuator name="wrist_2_motor">
      <mechanicalReduction>1</mechanicalReduction>
    </actuator>
  </transmission>
  <transmission name="wrist_3_trans">
    <type>transmission_interface/SimpleTransmission</type>
    <joint name="wrist_3_joint">
      <hardwareInterface>hardware_interface/PositionJointInterface</hardwareInterface>
    </joint>
    <actuator name="wrist_3_motor">
      <mechanicalReduction>1</mechanicalReduction>
    </actuator>
  </transmission>
  <gazebo reference="shoulder_link">
    <selfCollide>true</selfCollide>
  </gazebo>
  <gazebo reference="upper_arm_link">
    <selfCollide>true</selfCollide>
  </gazebo>
  <gazebo reference="forearm_link">
    <selfCollide>true</selfCollide>
  </gazebo>
  <gazebo reference="wrist_1_link">
    <selfCollide>true</selfCollide>
  </gazebo>
  <gazebo reference="wrist_3_link">
    <selfCollide>true</selfCollide>
  </gazebo>
  <gazebo reference="wrist_2_link">
    <selfCollide>true</selfCollide>
  </gazebo>
  <gazebo reference="ee_link">
    <selfCollide>true</selfCollide>
  </gazebo>
  <!-- ROS base_link to UR 'Base' Coordinates transform -->
  <link name="base"/>
  <joint name="base_link-base_fixed_joint" type="fixed">
    <!-- NOTE: this rotation is only needed as long as base_link itself is
                 not corrected wrt the real robot (ie: rotated over 180
                 degrees)
      -->
    <origin rpy="0 0 -3.141592653589793" xyz="0 0 0"/>
    <parent link="base_link"/>
    <child link="base"/>
  </joint>
  <!-- Frame coincident with all-zeros TCP on UR controller -->
  <link name="tool0"/>
  <joint name="wrist_3_link-tool0_fixed_joint" type="fixed">
    <origin rpy="-1.5707963267948966 0 0" xyz="0 0.0823 0"/>
    <parent link="wrist_3_link"/>
    <child link="tool0"/>
  </joint>
  <!--xacro:ur_robot name="ur5"/-->
  <!--
  <link name="table_surface_link">
    <inertial>
      <mass value="1"/>
      <inertia ixx="0.0108" ixy="0" ixz="0" iyy="0.0083" iyz="0" izz="0.0042"/>
    </inertial>
    <visual>
      <material name="brown"/>
      <geometry>
        <box size="0.7 1.0 .05"/>
      </geometry>
    </visual>
    <collision name="table_surface">
      <geometry>
        <box size="0.7 1.0 .05"/>
      </geometry>
    </collision>
  </link>
  -->
  <!--
  <link name="front_wall_link">
    <inertial>
      <mass value="1"/>
      <inertia ixx="0.0108" ixy="0" ixz="0" iyy="0.0083" iyz="0" izz="0.0042"/>
    </inertial>
    <visual>
      <material name="collision_only_white" />
      <geometry>
        <box size=".1 2.0 2.0"/>
      </geometry>
    </visual>
    <collision name="wall">
      <geometry>
        <box size=".1 2.0 2.0"/>
      </geometry>
    </collision>
  </link>
  
  <link name="back_wall_link">
    <inertial>
      <mass value="1"/>
      <inertia ixx="0.0108" ixy="0" ixz="0" iyy="0.0083" iyz="0" izz="0.0042"/>
    </inertial>
    <visual>
      <material name="white" />
      <geometry>
        <box size=".1 2.0 2.0"/>
      </geometry>
    </visual>
    <collision name="wall">
      <geometry>
        <box size=".1 2.0 2.0"/>
      </geometry>
    </collision>
  </link>
  
  <link name="left_side_wall_link">
    <inertial>
      <mass value="1"/>
      <inertia ixx="0.0108" ixy="0" ixz="0" iyy="0.0083" iyz="0" izz="0.0042"/>
    </inertial>
    <visual>
      <material name="collision_only_white" />
      <geometry>
        <box size="2.0 0.1 2.0"/>
      </geometry>
    </visual>
    <collision name="wall">
      <geometry>
        <box size="2.0 0.1 2.0"/>
      </geometry>
    </collision>
  </link>
  
  <link name="right_side_wall_link">
    <inertial>
      <mass value="1"/>
      <inertia ixx="0.0108" ixy="0" ixz="0" iyy="0.0083" iyz="0" izz="0.0042"/>
    </inertial>
    <visual>
      <material name="collision_only_white" />
      <geometry>
        <box size="2.0 0.1 2.0"/>
      </geometry>
    </visual>
    <collision name="wall">
      <geometry>
        <box size="2.0 0.1 2.0"/>
      </geometry>
    </collision>
  </link>
!-->
  <link name="ft_link">
    <visual>
      <origin rpy="0 0 0" xyz="0 0 -0.01875"/>
      <material name="gray"/>
      <geometry>
        <cylinder length="0.0375" radius="0.05"/>
      </geometry>
    </visual>
    <collision>
      <origin rpy="0 0 0" xyz="0 0 -0.01875"/>
      <material name="gray"/>
      <geometry>
        <cylinder length="0.03" radius="0.03"/>
      </geometry>
    </collision>
  </link>
  <material name="silver">
    <color rgba="0.75 0.75 0.75 1"/>
  </material>
  <joint name="schunk_sih_right_base_joint" type="fixed">
    <parent link="ft_link"/>
    <child link="schunk_sih_right_palm_link"/>
    <origin rpy="0 0 1.570795" xyz="0 0 0"/>
  </joint>
  

    # Palm
    
  <link name="schunk_sih_right_palm_link">
    <visual>
      <geometry>
        <mesh filename="package://ur5_sih_schunk/robots/meshes/schunk_sih_right/visual/palm.dae" scale="0.001 0.001 0.001"/>
      </geometry>
      <material name="silver"/>
    </visual>
    <collision>
      <geometry>
        <mesh filename="package://ur5_sih_schunk/robots/meshes/schunk_sih_right/collision/palm.stl" scale="0.001 0.001 0.001"/>
      </geometry>
    </collision>
    <inertial>
      <mass value="1.0"/>
      <origin rpy="0 0 0" xyz="0.0 0.0 0.0"/>
      <inertia ixx="0.0001" ixy="0.0001" ixz="0.0001" iyy="0.0001" iyz="0.0001" izz="0.0001"/>
    </inertial>
  </link>
  

    # Index finger
    
  <link name="schunk_sih_right_index_proximal_link">
    <visual>
      <geometry>
        <mesh filename="package://ur5_sih_schunk/robots/meshes/schunk_sih_right/visual/if_proximal.dae" scale="0.001 0.001 0.001"/>
      </geometry>
      <material name="silver"/>
      <origin rpy="0 0 0" xyz="-0.0435 0 -0.141"/>
    </visual>
    <collision>
      <geometry>
        <mesh filename="package://ur5_sih_schunk/robots/meshes/schunk_sih_right/collision/if_proximal.stl" scale="0.001 0.001 0.001"/>
      </geometry>
      <origin rpy="0 0 0" xyz="-0.0435 0 -0.141"/>
    </collision>
    <inertial>
      <mass value="0.100"/>
      <origin rpy="0 0 0" xyz="0.0 0.0 0.0"/>
      <inertia ixx="0.0001" ixy="0.0001" ixz="0.0001" iyy="0.0001" iyz="0.0001" izz="0.0001"/>
    </inertial>
  </link>
  <joint name="schunk_sih_right_index_finger" type="revolute">
    <parent link="schunk_sih_right_palm_link"/>
    <child link="schunk_sih_right_index_proximal_link"/>
    <origin xyz="0.0435 0 0.141"/>
    <axis xyz="1 0 0"/>
    <limit effort="330.0" lower="-1.57" upper="0.0" velocity="2.09439510239"/>
    <dynamics damping="0.1" friction="0"/>
  </joint>
  <link name="schunk_sih_right_index_distal_link">
    <visual>
      <geometry>
        <mesh filename="package://ur5_sih_schunk/robots/meshes/schunk_sih_right/visual/if_distal.dae" scale="0.001 0.001 0.001"/>
      </geometry>
      <material name="silver"/>
      <origin rpy="0 0 0" xyz="-0.0435 0 -0.189"/>
    </visual>
    <collision>
      <geometry>
        <mesh filename="package://ur5_sih_schunk/robots/meshes/schunk_sih_right/collision/if_distal.stl" scale="0.001 0.001 0.001"/>
      </geometry>
      <origin rpy="0 0 0" xyz="-0.0435 0 -0.189"/>
    </collision>
    <inertial>
      <mass value="0.100"/>
      <origin rpy="0 0 0" xyz="0.0 0.0 0.0"/>
      <inertia ixx="0.0001" ixy="0.0001" ixz="0.0001" iyy="0.0001" iyz="0.0001" izz="0.0001"/>
    </inertial>
  </link>
  <joint name="schunk_sih_right_index_distal_joint" type="revolute">
    <parent link="schunk_sih_right_index_proximal_link"/>
    <child link="schunk_sih_right_index_distal_link"/>
    <origin xyz="0 0 0.048"/>
    <axis xyz="1 0 0"/>
    <mimic joint="schunk_sih_right_index_finger" multiplier="1.0" offset="0"/>
    <limit effort="330.0" lower="-1.571" upper="0.0" velocity="2.09439510239"/>
    <dynamics damping="0.1" friction="0"/>
  </joint>
  

    # Middle finger
    
  <link name="schunk_sih_right_middle_proximal_link">
    <visual>
      <geometry>
        <mesh filename="package://ur5_sih_schunk/robots/meshes/schunk_sih_right/visual/mf_proximal.dae" scale="0.001 0.001 0.001"/>
      </geometry>
      <material name="silver"/>
      <origin rpy="0 0 0" xyz="-0.0187 0 -0.141"/>
    </visual>
    <collision>
      <geometry>
        <mesh filename="package://ur5_sih_schunk/robots/meshes/schunk_sih_right/collision/mf_proximal.stl" scale="0.001 0.001 0.001"/>
      </geometry>
      <origin rpy="0 0 0" xyz="-0.0187 0 -0.141"/>
    </collision>
    <inertial>
      <mass value="0.100"/>
      <origin rpy="0 0 0" xyz="0.0 0.0 0.0"/>
      <inertia ixx="0.0001" ixy="0.0001" ixz="0.0001" iyy="0.0001" iyz="0.0001" izz="0.0001"/>
    </inertial>
  </link>
  <joint name="schunk_sih_right_middle_finger" type="revolute">
    <parent link="schunk_sih_right_palm_link"/>
    <child link="schunk_sih_right_middle_proximal_link"/>
    <origin xyz="0.0187 0 0.141"/>
    <axis xyz="1 0 0"/>
    <limit effort="330.0" lower="-1.571" upper="0.0" velocity="2.09439510239"/>
    <dynamics damping="0.1" friction="0"/>
  </joint>
  <link name="schunk_sih_right_middle_distal_link">
    <visual>
      <geometry>
        <mesh filename="package://ur5_sih_schunk/robots/meshes/schunk_sih_right/visual/mf_distal.dae" scale="0.001 0.001 0.001"/>
      </geometry>
      <material name="silver"/>
      <origin rpy="0 0 0" xyz="-0.0187 0 -0.1935"/>
    </visual>
    <collision>
      <geometry>
        <mesh filename="package://ur5_sih_schunk/robots/meshes/schunk_sih_right/collision/mf_distal.stl" scale="0.001 0.001 0.001"/>
      </geometry>
      <origin rpy="0 0 0" xyz="-0.0187 0 -0.1935"/>
    </collision>
    <inertial>
      <mass value="0.100"/>
      <origin rpy="0 0 0" xyz="0.0 0.0 0.0"/>
      <inertia ixx="0.0001" ixy="0.0001" ixz="0.0001" iyy="0.0001" iyz="0.0001" izz="0.0001"/>
    </inertial>
  </link>
  <joint name="schunk_sih_right_middle_distal_joint" type="revolute">
    <parent link="schunk_sih_right_middle_proximal_link"/>
    <child link="schunk_sih_right_middle_distal_link"/>
    <origin xyz="0 0 0.0525"/>
    <axis xyz="1 0 0"/>
    <mimic joint="schunk_sih_right_middle_finger" multiplier="1.0" offset="0"/>
    <limit effort="330.0" lower="-1.571" upper="0.0" velocity="2.09439510239"/>
    <dynamics damping="0.1" friction="0"/>
  </joint>
  

    # Ring finger
    
  <link name="schunk_sih_right_ring_proximal_link">
    <visual>
      <geometry>
        <mesh filename="package://ur5_sih_schunk/robots/meshes/schunk_sih_right/visual/rf_proximal.dae" scale="0.001 0.001 0.001"/>
      </geometry>
      <material name="silver"/>
      <origin rpy="0 0 0" xyz="0.0069 0 -0.134"/>
    </visual>
    <collision>
      <geometry>
        <mesh filename="package://ur5_sih_schunk/robots/meshes/schunk_sih_right/collision/rf_proximal.stl" scale="0.001 0.001 0.001"/>
      </geometry>
      <origin rpy="0 0 0" xyz="0.0069 0 -0.134"/>
    </collision>
    <inertial>
      <mass value="0.100"/>
      <origin rpy="0 0 0" xyz="0.0 0.0 0.0"/>
      <inertia ixx="0.0001" ixy="0.0001" ixz="0.0001" iyy="0.0001" iyz="0.0001" izz="0.0001"/>
    </inertial>
  </link>
  <joint name="schunk_sih_right_ring_finger" type="revolute">
    <parent link="schunk_sih_right_palm_link"/>
    <child link="schunk_sih_right_ring_proximal_link"/>
    <origin xyz="-0.0069 0 0.134"/>
    <axis xyz="1 0 0"/>
    <limit effort="330.0" lower="-1.571" upper="0.0" velocity="2.09439510239"/>
    <dynamics damping="0.1" friction="0"/>
  </joint>
  <link name="schunk_sih_right_ring_distal_link">
    <visual>
      <geometry>
        <mesh filename="package://ur5_sih_schunk/robots/meshes/schunk_sih_right/visual/rf_distal.dae" scale="0.001 0.001 0.001"/>
      </geometry>
      <material name="silver"/>
      <origin rpy="0 0 0" xyz="0.0069 0 -0.182"/>
    </visual>
    <collision>
      <geometry>
        <mesh filename="package://ur5_sih_schunk/robots/meshes/schunk_sih_right/collision/rf_distal.stl" scale="0.001 0.001 0.001"/>
      </geometry>
      <origin rpy="0 0 0" xyz="0.0069 0 -0.182"/>
    </collision>
    <inertial>
      <mass value="0.100"/>
      <origin rpy="0 0 0" xyz="0.0 0.0 0.0"/>
      <inertia ixx="0.0001" ixy="0.0001" ixz="0.0001" iyy="0.0001" iyz="0.0001" izz="0.0001"/>
    </inertial>
  </link>
  <joint name="schunk_sih_right_ring_distal_joint" type="revolute">
    <parent link="schunk_sih_right_ring_proximal_link"/>
    <child link="schunk_sih_right_ring_distal_link"/>
    <origin xyz="0 0 0.048"/>
    <axis xyz="1 0 0"/>
    <mimic joint="schunk_sih_right_ring_finger" multiplier="1.0" offset="0"/>
    <limit effort="330.0" lower="-1.571" upper="0.0" velocity="2.09439510239"/>
    <dynamics damping="0.1" friction="0"/>
  </joint>
  

    # Little finger
    
  <link name="schunk_sih_right_pinky_proximal_link">
    <visual>
      <geometry>
        <mesh filename="package://ur5_sih_schunk/robots/meshes/schunk_sih_right/visual/lf_proximal.dae" scale="0.001 0.001 0.001"/>
      </geometry>
      <material name="silver"/>
      <origin rpy="0 0 0" xyz="0.032 0 -0.1254"/>
    </visual>
    <collision>
      <geometry>
        <mesh filename="package://ur5_sih_schunk/robots/meshes/schunk_sih_right/collision/lf_proximal.stl" scale="0.001 0.001 0.001"/>
      </geometry>
      <origin rpy="0 0 0" xyz="0.032 0 -0.1254"/>
    </collision>
    <inertial>
      <mass value="0.100"/>
      <origin rpy="0 0 0" xyz="0.0 0.0 0.0"/>
      <inertia ixx="0.0001" ixy="0.0001" ixz="0.0001" iyy="0.0001" iyz="0.0001" izz="0.0001"/>
    </inertial>
  </link>
  <joint name="schunk_sih_right_pinky_proximal_joint" type="revolute">
    <parent link="schunk_sih_right_palm_link"/>
    <child link="schunk_sih_right_pinky_proximal_link"/>
    <origin xyz="-0.032 0 0.1254"/>
    <axis xyz="1 0 0"/>
    <mimic joint="schunk_sih_right_ring_finger" multiplier="1.0" offset="0"/>
    <limit effort="330.0" lower="-1.571" upper="0.0" velocity="2.09439510239"/>
    <dynamics damping="0.1" friction="0"/>
  </joint>
  <link name="schunk_sih_right_pinky_distal_link">
    <visual>
      <geometry>
        <mesh filename="package://ur5_sih_schunk/robots/meshes/schunk_sih_right/visual/lf_distal.dae" scale="0.001 0.001 0.001"/>
      </geometry>
      <material name="silver"/>
      <origin rpy="0 0 0" xyz="0.032 0 -0.1655"/>
    </visual>
    <collision>
      <geometry>
        <mesh filename="package://ur5_sih_schunk/robots/meshes/schunk_sih_right/collision/lf_distal.stl" scale="0.001 0.001 0.001"/>
      </geometry>
      <origin rpy="0 0 0" xyz="0.032 0 -0.1655"/>
    </collision>
    <inertial>
      <mass value="0.100"/>
      <origin rpy="0 0 0" xyz="0.0 0.0 0.0"/>
      <inertia ixx="0.0001" ixy="0.0001" ixz="0.0001" iyy="0.0001" iyz="0.0001" izz="0.0001"/>
    </inertial>
  </link>
  <joint name="schunk_sih_right_pinky_distal_joint" type="revolute">
    <parent link="schunk_sih_right_pinky_proximal_link"/>
    <child link="schunk_sih_right_pinky_distal_link"/>
    <origin xyz="0 0 0.0401"/>
    <axis xyz="1 0 0"/>
    <mimic joint="schunk_sih_right_pinky_proximal_joint" multiplier="1.0" offset="0"/>
    <limit effort="330.0" lower="-1.571" upper="0.0" velocity="2.09439510239"/>
    <dynamics damping="0.1" friction="0"/>
  </joint>
  

    # Thumb
    
  <link name="schunk_sih_right_thumb_proximal_link">
    <visual>
      <geometry>
        <mesh filename="package://ur5_sih_schunk/robots/meshes/schunk_sih_right/visual/th_proximal.dae" scale="0.001 0.001 0.001"/>
      </geometry>
      <material name="silver"/>
      <origin rpy="0 0 0" xyz="0.034 -0.019 -0.08"/>
    </visual>
    <collision>
      <geometry>
        <mesh filename="package://ur5_sih_schunk/robots/meshes/schunk_sih_right/collision/th_proximal.stl" scale="0.001 0.001 0.001"/>
      </geometry>
      <origin rpy="0 0 0" xyz="0.034 -0.019 -0.08"/>
    </collision>
    <inertial>
      <mass value="0.100"/>
      <origin rpy="0 0 0" xyz="0.0 0.0 0.0"/>
      <inertia ixx="0.0001" ixy="0.0001" ixz="0.0001" iyy="0.0001" iyz="0.0001" izz="0.0001"/>
    </inertial>
  </link>
  <joint name="schunk_sih_right_thumb_opposition" type="revolute">
    <parent link="schunk_sih_right_palm_link"/>
    <child link="schunk_sih_right_thumb_proximal_link"/>
    <origin xyz="-0.034 0.019 0.08"/>
    <axis xyz="0 0 1"/>
    <limit effort="330.0" lower="-1.571" upper="0.0" velocity="2.09439510239"/>
    <dynamics damping="0.1" friction="0"/>
  </joint>
  <link name="schunk_sih_right_thumb_inter_link">
    <visual>
      <geometry>
        <mesh filename="package://ur5_sih_schunk/robots/meshes/schunk_sih_right/visual/th_inter.dae" scale="0.001 0.001 0.001"/>
      </geometry>
      <material name="silver"/>
      <origin rpy="0 0 0" xyz="0.058 -0.024 -0.081"/>
    </visual>
    <collision>
      <geometry>
        <mesh filename="package://ur5_sih_schunk/robots/meshes/schunk_sih_right/collision/th_inter_cvx.stl" scale="0.001 0.001 0.001"/>
      </geometry>
      <origin rpy="0 0 0" xyz="0.058 -0.024 -0.081"/>
    </collision>
    <inertial>
      <mass value="0.100"/>
      <origin rpy="0 0 0" xyz="0.0 0.0 0.0"/>
      <inertia ixx="0.0001" ixy="0.0001" ixz="0.0001" iyy="0.0001" iyz="0.0001" izz="0.0001"/>
    </inertial>
  </link>
  <joint name="schunk_sih_right_thumb_flexion" type="revolute">
    <parent link="schunk_sih_right_thumb_proximal_link"/>
    <child link="schunk_sih_right_thumb_inter_link"/>
    <origin xyz="-0.024 0.005 0.001"/>
    <axis xyz="0 1 0"/>
    <limit effort="330.0" lower="0.0" upper="1.571" velocity="2.09439510239"/>
    <dynamics damping="0.1" friction="0"/>
  </joint>
  <link name="schunk_sih_right_thumb_distal_link">
    <visual>
      <geometry>
        <mesh filename="package://ur5_sih_schunk/robots/meshes/schunk_sih_right/visual/th_distal.dae" scale="0.001 0.001 0.001"/>
      </geometry>
      <material name="silver"/>
      <origin rpy="0 0 0" xyz="0.0971 -0.024 -0.081"/>
    </visual>
    <collision>
      <geometry>
        <mesh filename="package://ur5_sih_schunk/robots/meshes/schunk_sih_right/collision/th_distal.stl" scale="0.001 0.001 0.001"/>
      </geometry>
      <origin rpy="0 0 0" xyz="0.0971 -0.024 -0.081"/>
    </collision>
    <inertial>
      <mass value="0.100"/>
      <origin rpy="0 0 0" xyz="0.0 0.0 0.0"/>
      <inertia ixx="0.0001" ixy="0.0001" ixz="0.0001" iyy="0.0001" iyz="0.0001" izz="0.0001"/>
    </inertial>
  </link>
  <joint name="schunk_sih_right_thumb_distal" type="revolute">
    <parent link="schunk_sih_right_thumb_inter_link"/>
    <child link="schunk_sih_right_thumb_distal_link"/>
    <origin xyz="-0.0391 0 0"/>
    <axis xyz="0 1 0"/>
    <limit effort="330.0" lower="0.0" upper="1.571" velocity="2.09439510239"/>
    <dynamics damping="0.1" friction="0"/>
  </joint>
  <joint name="ft_joint" type="fixed">
    <origin rpy="0 0 0" xyz="0 0 0.0375"/>
    <parent link="tool0"/>
    <child link="ft_link"/>
  </joint>
  <!--
  <joint name="table_surface_joint" type="fixed">
    <origin rpy="0 0 0" xyz=".28 .33 -.03"/>
    <parent link="base_link"/>
    <child link="table_surface_link"/>
  </joint>
  !-->
  <!--
  <joint name="back_wall_joint" type="fixed" >
    <origin xyz=".63 .6 0"  rpy= "0 0 0" />
    <parent link="base_link" />
    <child link="back_wall_link" />
  </joint>
  
  <joint name="front_wall_joint" type="fixed" >
    <origin xyz="-0.22 .6 0"  rpy= "0 0 0" />
    <parent link="base_link" />
    <child link="front_wall_link" />
  </joint>
  
  <joint name="left_side_wall_joint" type="fixed" >
    <origin xyz=".28 1.0 0"  rpy= "0 0 0" />
    <parent link="base_link" />
    <child link="left_side_wall_link" />
  </joint>
  
  <joint name="right_side_wall_joint" type="fixed" >
    <origin xyz=".28 -0.3 0"  rpy= "0 0 0" />
    <parent link="base_link" />
    <child link="right_side_wall_link" />
  </joint>
!-->
</robot>
